Workbook

Sheet Harga Bahan
A1: DAFTAR HARGA BAHAN BAKU (dikonversi ke harga per gram/pcs)
A3: No | B3: Item | C3: Harga Beli (Rp) | D3: Isi Kemasan | E3: Satuan | F3: Harga per Satuan (Rp)
A4: 1 | B4: Terigu Golden eagle | C4: 15000 | D4: 1000 | E4: gram | F4: =C4/D4 -> 15
A5: 2 | B5: Terigu gandum whole wheat bungasari | C5: 99000 | D5: 2500 | E5: gram | F5: =C5/D5 -> 39.6
A6: 3 | B6: Gandum Kasar | C6: 47500 | D6: 1000 | E6: gram | F6: =C6/D6 -> 47.5
A7: 4 | B7: Whole wheat natural | C7: 105000 | D7: 5000 | E7: gram | F7: =C7/D7 -> 21
A8: 5 | B8: Ragi permifan 2 in 1 | C8: 53500 | D8: 500 | E8: gram | F8: =C8/D8 -> 107
A9: 6 | B9: Gula pasir | C9: 18000 | D9: 1000 | E9: gram | F9: =C9/D9 -> 18
A10: 7 | B10: Telor | C10: 30000 | D10: 1000 | E10: gram | F10: =C10/D10 -> 30
A11: 8 | B11: Mother choice | C11: 35000 | D11: 1000 | E11: gram | F11: =C11/D11 -> 35
A12: 9 | B12: Garam | C12: 3500 | D12: 200 | E12: gram | F12: =C12/D12 -> 17.5
A13: 10 | B13: Coklat | C13: 150000 | D13: 5000 | E13: gram | F13: =C13/D13 -> 30
A14: 11 | B14: Keju | C14: 120000 | D14: 2000 | E14: gram | F14: =C14/D14 -> 60
A15: 12 | B15: Elmer glaze | C15: 15000 | D15: 200 | E15: gram | F15: =C15/D15 -> 75
... A22: 19 | B22: Bombay | C22: 15000 | D22: 2 | E22: biji | F22: =C22/D22 -> 7500
A24: Keterangan:
A25: Kuning | B25: harga placeholder, perlu diisi harga sebenarnya
A26: Catatan | B26: Harga di atas sudah pakai HARGA TERTINGGI yang pernah dibayar (bukan rata-rata) - kebijakan konservatif yang disengaja untuk buffer margin & posisi nego, bukan kesalahan data.

Sheet Resep & HPP
A1: PERHITUNGAN HPP ROTI
A2: Asumsi: 1 loyang = 1 pcs roti. Bahan dicari otomatis dari sheet 'Harga Bahan' (INDEX/MATCH).
A4: Resep Dasar - Varian A (pakai Whole Wheat Bungasari) (hasil 8 loyang)
A5: Item | B5: Pemakaian | C5: Satuan | D5: Harga per Satuan (Rp) | E5: Biaya (Rp)
A6: Terigu gandum whole wheat bungasari | B6: 300 | C6: g | D6: =INDEX('Harga Bahan'!$F$4:$F$22,MATCH(A6,'Harga Bahan'!$B$4:$B$22,0)) -> 39.6 | E6: =B6*D6 -> 11880
A7: Terigu Golden eagle | B7: 1200 | C7: g | D7: =INDEX('Harga Bahan'!$F$4:$F$22,MATCH(A7,'Harga Bahan'!$B$4:$B$22,0)) -> 15 | E7: =B7*D7 -> 18000
A8: Ragi permifan 2 in 1 | B8: 30 | C8: g | D8: =INDEX('Harga Bahan'!$F$4:$F$22,MATCH(A8,'Harga Bahan'!$B$4:$B$22,0)) -> 107 | E8: =B8*D8 -> 3210
A9: Gula pasir | B9: 200 | C9: g | D9: =INDEX('Harga Bahan'!$F$4:$F$22,MATCH(A9,'Harga Bahan'!$B$4:$B$22,0)) -> 18 | E9: =B9*D9 -> 3600
A10: Telor | B10: 180 | C10: g | D10: =INDEX('Harga Bahan'!$F$4:$F$22,MATCH(A10,'Harga Bahan'!$B$4:$B$22,0)) -> 30 | E10: =B10*D10 -> 5400
A11: Mother choice | B11: 225 | C11: g | D11: =INDEX('Harga Bahan'!$F$4:$F$22,MATCH(A11,'Harga Bahan'!$B$4:$B$22,0)) -> 35 | E11: =B11*D11 -> 7875
A12: Garam | B12: 26 | C12: g | D12: =INDEX('Harga Bahan'!$F$4:$F$22,MATCH(A12,'Harga Bahan'!$B$4:$B$22,0)) -> 17.5 | E12: =B12*D12 -> 455
A13: Subtotal | E13: =SUM(E6:E12) -> 50420
A14: Jumlah loyang/pcs pada resep ini | E14: 8
A15: Biaya Adonan per Pcs (Varian A) | E15: =E13/E14 -> 6302.5
A17: Resep Dasar - Varian B (pakai Whole Wheat Natural) (hasil 8 loyang)
A18: Item | B18: Pemakaian | C18: Satuan | D18: Harga per Satuan (Rp) | E18: Biaya (Rp)
A19: Whole wheat natural | B19: 300 | C19: g | D19: =INDEX('Harga Bahan'!$F$4:$F$22,MATCH(A19,'Harga Bahan'!$B$4:$B$22,0)) -> 21 | E19: =B19*D19 -> 6300
A20: Terigu Golden eagle | B20: 1200 | C20: g | D20: =INDEX('Harga Bahan'!$F$4:$F$22,MATCH(A20,'Harga Bahan'!$B$4:$B$22,0)) -> 15 | E20: =B20*D20 -> 18000
A21: Ragi permifan 2 in 1 | B21: 30 | C21: g | D21: =INDEX('Harga Bahan'!$F$4:$F$22,MATCH(A21,'Harga Bahan'!$B$4:$B$22,0)) -> 107 | E21: =B21*D21 -> 3210
A22: Gula pasir | B22: 200 | C22: g | D22: =INDEX('Harga Bahan'!$F$4:$F$22,MATCH(A22,'Harga Bahan'!$B$4:$B$22,0)) -> 18 | E22: =B22*D22 -> 3600
A23: Telor | B23: 180 | C23: g | D23: =INDEX('Harga Bahan'!$F$4:$F$22,MATCH(A23,'Harga Bahan'!$B$4:$B$22,0)) -> 30 | E23: =B23*D23 -> 5400
A24: Mother choice | B24: 225 | C24: g | D24: =INDEX('Harga Bahan'!$F$4:$F$22,MATCH(A24,'Harga Bahan'!$B$4:$B$22,0)) -> 35 | E24: =B24*D24 -> 7875
A25: Garam | B25: 26 | C25: g | D25: =INDEX('Harga Bahan'!$F$4:$F$22,MATCH(A25,'Harga Bahan'!$B$4:$B$22,0)) -> 17.5 | E25: =B25*D25 -> 455
A26: Subtotal | E26: =SUM(E19:E25) -> 44840
A27: Jumlah loyang/pcs pada resep ini | E27: 8
A28: Biaya Adonan per Pcs (Varian B) | E28: =E26/E27 -> 5605
A30: Filling Keju (untuk 15 roti)
A31: Item | B31: Pemakaian | C31: Satuan | D31: Harga per Satuan (Rp) | E31: Biaya (Rp)
A32: Keju | B32: 300 | C32: g | D32: =INDEX('Harga Bahan'!$F$4:$F$22,MATCH(A32,'Harga Bahan'!$B$4:$B$22,0)) -> 60 | E32: =B32*D32 -> 18000
A33: Elmer glaze | B33: 500 | C33: g | D33: =INDEX('Harga Bahan'!$F$4:$F$22,MATCH(A33,'Harga Bahan'!$B$4:$B$22,0)) -> 75 | E33: =B33*D33 -> 37500
A34: SKM | B34: 100 | C34: g | D34: =INDEX('Harga Bahan'!$F$4:$F$22,MATCH(A34,'Harga Bahan'!$B$4:$B$22,0)) -> 124 | E34: =B34*D34 -> 12400
A35: Subtotal | E35: =SUM(E32:E34) -> 67900
A36: Jumlah roti pada resep ini | E36: 15
A37: Biaya Filling Keju per Pcs | E37: =E35/E36 -> 4526.6667
A39: Filling Daging (untuk 30 loyang (basis 1kg daging))
A40: Item | B40: Pemakaian | C40: Satuan | D40: Harga per Satuan (Rp) | E40: Biaya (Rp)
A41: Daging | B41: 1000 | C41: g | D41: =INDEX('Harga Bahan'!$F$4:$F$22,MATCH(A41,'Harga Bahan'!$B$4:$B$22,0)) -> 120 | E41: =B41*D41 -> 120000
A42: Bombay | B42: 2 | C42: biji | D42: =INDEX('Harga Bahan'!$F$4:$F$22,MATCH(A42,'Harga Bahan'!$B$4:$B$22,0)) -> 7500 | E42: =B42*D42 -> 15000
A43: Kundur | B43: 500 | C43: g | D43: =INDEX('Harga Bahan'!$F$4:$F$22,MATCH(A43,'Harga Bahan'!$B$4:$B$22,0)) -> 56 | E43: =B43*D43 -> 28000
A44: Subtotal | E44: =SUM(E41:E43) -> 163000
...

Sheet Tenaga Kerja & Overhead
A1: TENAGA KERJA & OVERHEAD PRODUKSI
A2: Jam produksi: 04.00 - 08.00 (4 jam). Buka tiap hari kecuali Senin -> 26 hari kerja/bulan.
A4: A. BIAYA PRODUKSI - MASUK HPP
A5: Komponen | B5: Keterangan | C5: Satuan | D5: Biaya (Rp)
A6: Baker - Kak Mei | B6: Upah harian, shift 4 jam (04.00-08.00) | C6: per hari | D6: 50000
A7: Baker - Mama Farel | B7: Upah harian, shift 4 jam (04.00-08.00) | C7: per hari | D7: 50000
A8: Gas melon 3kg | B8: Rp20.000/tabung, habis untuk 3 hari produksi -> 20.000/3 | C8: per hari | D8: 6666.6667
A9: Lembur (opsional, isi jumlah jam jika ada) | C9: 0 | D9: =C9*10000 -> 0
A10: Total Biaya Produksi per Hari | D10: =SUM(D6:D8)+D9 -> 106666.67
A12: Estimasi Produksi per Hari (blended) | D12: =D82 -> 64
A13: Biaya Tenaga Kerja + Gas per Pcs | D13: =D10/D12 -> 1666.6667
A14: Depresiasi Alat per Pcs | D14: =E53/D12 -> 114.58801
A15: Listrik per Pcs | D15: =D62/D12 -> 132.31332
A16: TOTAL OVERHEAD PRODUKSI PER PCS (masuk HPP) | D16: =D13+D14+D15 -> 1913.568
A19: B. BIAYA OPERASIONAL / JUALAN - DI LUAR HPP (untuk pertimbangan harga jual)
A20: Komponen | B20: Keterangan | C20: Satuan | D20: Biaya (Rp)
A21: Farel | B21: Jaga toko/jualan | C21: per bulan | D21: 0
A22: Nanda | B22: Jaga toko/jualan | C22: per bulan | D22: 800000
A23: Owner | B23: Jaga toko, kadang baker juga | C23: per bulan | D23: 1000000
A24: Subtotal Gaji Staf per Bulan | D24: =SUM(D21:D23) -> 1800000
A26: Bensin Motor (ambil ready stok di rumah + antar jualan ke tempat, 2 kloter tetap/hari)
A27: Jarak tempuh pp per kloter (km) | D27: 8.8
A28: Jumlah kloter per hari | D28: 2
A29: Konsumsi bensin realistis - jarak pendek/macet (km/liter) | D29: 37.5
A30: Harga bensin per liter (Pertalite) | D30: 10000
A31: Biaya Bensin per Hari | D31: =(D27*D28)/D29*D30 -> 4693.3333
A32: Hari kerja per bulan | D32: =D71 -> 25.98
A33: Biaya Bensin per Bulan | D33: =D31*D32 -> 121932.8
A34: Total Biaya Operasional per Bulan (Gaji Staf + Bensin) | D34: =D24+D33 -> 1921932.8
A35: Estimasi Produksi per Hari (blended, sama dgn Bagian A) | D35: =D12 -> 64
A36: Gaji Staf per Pcs | D36: =D24/D32/D35 -> 1082.5635
A37: Bensin Motor per Pcs | D37: =D33/D32/D35 -> 73.333333
A38: TOTAL OPEX JUALAN PER PCS (di luar HPP) | D38: =D36+D37 -> 1155.8968
A39: Catatan: baris B tidak ditambahkan ke HPP karena ini biaya penjualan/distribusi, bukan biaya produksi. Bensin beli-bahan (variable, gantian motor) belum dimasukkan karena frekuensinya tidak tetap.
A40: C. DETAIL DEPRESIASI ALAT / PROVISI PENGGANTIAN (pendukung baris D14)
A41: Alat | B41: Harga Beli/Pasar (Rp) | C41: Umur Ekonomis (thn) | D41: Alokasi Usaha (%) | E41: Depresiasi/Tahun (Rp)
A42: Oven Deck Crown + kaki | B42: 10000000 | C42: 12 | D42: 1 | E42: =B42/C42*D42 -> 833333.33
A43: Mixer (bekas, kondisi seperti baru) | B43: 3000000 | C43: 8 | D43: 1 | E43: =B43/C43*D43 -> 375000
A44: Loyang (25pcs x Rp22.000) | B44: 550000 | C44: 8 | D44: 1 | E44: =B44/C44*D44 -> 68750
A45: Proofer | B45: 3800000 | C45: 10 | D45: 1 | E45: =B45/C45*D45 -> 380000
...

Sheet HPP Gabungan (Full Cost)
A1: HPP GABUNGAN - TERMASUK BIAYA OPERASIONAL/JUALAN
A2: Sheet ini = HPP murni (dari sheet 'Resep & HPP') + gaji Farel/Nanda/Owner (dari 'Tenaga Kerja & Overhead'). Dipakai kalau mau lihat total biaya per pcs termasuk semua orang yang digaji, bukan cuma produksi.
A4: Jenis Roti | B4: HPP Murni (Bahan+TK+Gas) | C4: Biaya Operasional/Jualan | D4: HPP Gabungan (Full Cost)
A5: ='Resep & HPP'!$A$65 -> Roti Original - Adonan Bungasari | B5: ='Resep & HPP'!$F$65 -> 9676.068 | C5: ='Tenaga Kerja & Overhead'!$D$38 -> 1155.8968 | D5: =B5+C5 -> 10831.965
A6: ='Resep & HPP'!$A$66 -> Roti Original - Adonan Natural | B6: ='Resep & HPP'!$F$66 -> 8978.568 | C6: ='Tenaga Kerja & Overhead'!$D$38 -> 1155.8968 | D6: =B6+C6 -> 10134.465
A7: ='Resep & HPP'!$A$67 -> Roti Keju - Adonan Bungasari | B7: ='Resep & HPP'!$F$67 -> 14202.735 | C7: ='Tenaga Kerja & Overhead'!$D$38 -> 1155.8968 | D7: =B7+C7 -> 15358.632
A8: ='Resep & HPP'!$A$68 -> Roti Keju - Adonan Natural | B8: ='Resep & HPP'!$F$68 -> 13505.235 | C8: ='Tenaga Kerja & Overhead'!$D$38 -> 1155.8968 | D8: =B8+C8 -> 14661.132
A9: ='Resep & HPP'!$A$69 -> Roti Daging - Adonan Bungasari | B9: ='Resep & HPP'!$F$69 -> 15442.735 | C9: ='Tenaga Kerja & Overhead'!$D$38 -> 1155.8968 | D9: =B9+C9 -> 16598.632
A10: ='Resep & HPP'!$A$70 -> Roti Daging - Adonan Natural | B10: ='Resep & HPP'!$F$70 -> 14745.235 | C10: ='Tenaga Kerja & Overhead'!$D$38 -> 1155.8968 | D10: =B10+C10 -> 15901.132
A11: ='Resep & HPP'!$A$71 -> Roti Coklat - Adonan Bungasari | B11: ='Resep & HPP'!$F$71 -> 11238.568 | C11: ='Tenaga Kerja & Overhead'!$D$38 -> 1155.8968 | D11: =B11+C11 -> 12394.465
A12: ='Resep & HPP'!$A$72 -> Roti Coklat - Adonan Natural | B12: ='Resep & HPP'!$F$72 -> 10541.068 | C12: ='Tenaga Kerja & Overhead'!$D$38 -> 1155.8968 | D12: =B12+C12 -> 11696.965

Sheet Margin & Simulasi Sewa
A1: MARGIN PROFIT & SIMULASI BAGI HASIL
A2: Isi kolom kuning (Harga Jual, Qty Terjual Weekday & Weekend) sesuai kondisi asli. Semua hitungan lain otomatis.
A4: A. MARGIN PER PCS
A5: Jenis Roti | B5: HPP Full Cost | C5: Harga Jual (isi manual) | D5: Margin per Pcs | E5: Margin % | F5: Qty Terjual Weekday/Hari (isi manual) | G5: Qty Terjual Weekend/Hari (isi manual)
A6: Roti Original - Adonan Bungasari | B6: ='HPP Gabungan (Full Cost)'!$D$5 -> 10831.965 | C6: 20000 | D6: =C6-B6 -> 9168.0352 | E6: =D6/C6 -> 0.45840176 | F6: 0 | G6: 0
A7: Roti Original - Adonan Natural | B7: ='HPP Gabungan (Full Cost)'!$D$6 -> 10134.465 | C7: 20000 | D7: =C7-B7 -> 9865.5352 | E7: =D7/C7 -> 0.49327676 | F7: 12 | G7: 24
A8: Roti Keju - Adonan Bungasari | B8: ='HPP Gabungan (Full Cost)'!$D$7 -> 15358.632 | C8: 25000 | D8: =C8-B8 -> 9641.3685 | E8: =D8/C8 -> 0.38565474 | F8: 0 | G8: 0
A9: Roti Keju - Adonan Natural | B9: ='HPP Gabungan (Full Cost)'!$D$8 -> 14661.132 | C9: 25000 | D9: =C9-B9 -> 10338.868 | E9: =D9/C9 -> 0.41355474 | F9: 12 | G9: 24
A10: Roti Daging - Adonan Bungasari | B10: ='HPP Gabungan (Full Cost)'!$D$9 -> 16598.632 | C10: 35000 | D10: =C10-B10 -> 18401.368 | E10: =D10/C10 -> 0.52575339 | F10: 0 | G10: 0
A11: Roti Daging - Adonan Natural | B11: ='HPP Gabungan (Full Cost)'!$D$10 -> 15901.132 | C11: 35000 | D11: =C11-B11 -> 19098.868 | E11: =D11/C11 -> 0.54568196 | F11: 12 | G11: 24
A12: Roti Coklat - Adonan Bungasari | B12: ='HPP Gabungan (Full Cost)'!$D$11 -> 12394.465 | C12: 25000 | D12: =C12-B12 -> 12605.535 | E12: =D12/C12 -> 0.50422141 | F12: 0 | G12: 0
A13: Roti Coklat - Adonan Natural | B13: ='HPP Gabungan (Full Cost)'!$D$12 -> 11696.965 | C13: 25000 | D13: =C13-B13 -> 13303.035 | E13: =D13/C13 -> 0.53212141 | F13: 12 | G13: 24
A14: TOTAL (cek vs kapasitas produksi Weekday & Weekend) | F14: =SUM(F6:F13) -> 48 | G14: =SUM(G6:G13) -> 96 | H14: ="Target: "&'Tenaga Kerja & Overhead'!$D$69&" (weekday) / "&'Tenaga Kerja & Overhead'!$D$70&" (weekend)" -> Target: 48 (weekday) / 96 (weekend)
A15: B. TOTAL PROFIT BULANAN (26 hari kerja/bulan)
A16: Jenis Roti | B16: Qty/Hari (rata-rata, info) | C16: Qty/Bulan | D16: Omzet/Bulan | E16: Profit/Bulan
A17: =A6 -> Roti Original - Adonan Bungasari | B17: =C17/'Tenaga Kerja & Overhead'!$D$71 -> 0 | C17: =F6*'Tenaga Kerja & Overhead'!$D$72+G6*'Tenaga Kerja & Overhead'!$D$73 -> 0 | D17: =C17*C6 -> 0 | E17: =C17*D6 -> 0
A18: =A7 -> Roti Original - Adonan Natural | B18: =C18/'Tenaga Kerja & Overhead'!$D$71 -> 16 | C18: =F7*'Tenaga Kerja & Overhead'!$D$72+G7*'Tenaga Kerja & Overhead'!$D$73 -> 415.68 | D18: =C18*C7 -> 8313600 | E18: =C18*D7 -> 4100905.7
A19: =A8 -> Roti Keju - Adonan Bungasari | B19: =C19/'Tenaga Kerja & Overhead'!$D$71 -> 0 | C19: =F8*'Tenaga Kerja & Overhead'!$D$72+G8*'Tenaga Kerja & Overhead'!$D$73 -> 0 | D19: =C19*C8 -> 0 | E19: =C19*D8 -> 0
A20: =A9 -> Roti Keju - Adonan Natural | B20: =C20/'Tenaga Kerja & Overhead'!$D$71 -> 16 | C20: =F9*'Tenaga Kerja & Overhead'!$D$72+G9*'Tenaga Kerja & Overhead'!$D$73 -> 415.68 | D20: =C20*C9 -> 10392000 | E20: =C20*D9 -> 4297660.9
A21: =A10 -> Roti Daging - Adonan Bungasari | B21: =C21/'Tenaga Kerja & Overhead'!$D$71 -> 0 | C21: =F10*'Tenaga Kerja & Overhead'!$D$72+G10*'Tenaga Kerja & Overhead'!$D$73 -> 0 | D21: =C21*C10 -> 0 | E21: =C21*D10 -> 0
A22: =A11 -> Roti Daging - Adonan Natural | B22: =C22/'Tenaga Kerja & Overhead'!$D$71 -> 16 | C22: =F11*'Tenaga Kerja & Overhead'!$D$72+G11*'Tenaga Kerja & Overhead'!$D$73 -> 415.68 | D22: =C22*C11 -> 14548800 | E22: =C22*D11 -> 7939017.7
A23: =A12 -> Roti Coklat - Adonan Bungasari | B23: =C23/'Tenaga Kerja & Overhead'!$D$71 -> 0 | C23: =F12*'Tenaga Kerja & Overhead'!$D$72+G12*'Tenaga Kerja & Overhead'!$D$73 -> 0 | D23: =C23*C12 -> 0 | E23: =C23*D12 -> 0
A24: =A13 -> Roti Coklat - Adonan Natural | B24: =C24/'Tenaga Kerja & Overhead'!$D$71 -> 16 | C24: =F13*'Tenaga Kerja & Overhead'!$D$72+G13*'Tenaga Kerja & Overhead'!$D$73 -> 415.68 | D24: =C24*C13 -> 10392000 | E24: =C24*D13 -> 5529805.7
A25: TOTAL | C25: =SUM(C17:C24) -> 1662.72 | D25: =SUM(D17:D24) -> 43646400 | E25: =SUM(E17:E24) -> 21867390
A27: C. SIMULASI BAGI HASIL KE BU DIANA
A28: Skema | B28: Basis | C28: Persen/Nominal | D28: Bagian Bu Diana/Bulan | E28: Sisa Buat Kamu/Bulan | F28: Sisa Buat Kamu %
A29: Opsi 1: Flat Sewa | B29: Nominal tetap/bulan | C29: 1500000 | D29: =C29 -> 1500000 | E29: =E25-D29 -> 20367390 | F29: =E29/E25 -> 0.93140471
A30: Opsi 2: % dari Omzet | B30: Persentase omzet | C30: 0.1 | D30: =C30*D25 -> 4364640 | E30: =E25-D30 -> 17502750 | F30: =E30/E25 -> 0.80040416
A31: Opsi 3 (diminta Bu Diana): 30% Profit | B31: Persentase profit | C31: 0.1 | D31: =C31*E25 -> 2186739 | E31: =E25-D31 -> 19680651 | F31: =E31/E25 -> 0.9
A33: Catatan: Opsi 1 & 2 nominal/persennya masih placeholder (kuning) - silakan disesuaikan pas nego. Opsi 3 dipakai sebagai pembanding supaya kelihatan selisihnya dengan permintaan awal Bu Diana.
A36: D. PENJELASAN & JUSTIFIKASI (bahan diskusi dengan Bu Diana)
A37: 1. Kenapa basis OMZET, bukan PROFIT?
A38: Omzet = harga jual x jumlah terjual, angkanya jelas dan mudah dicek dari nota/catatan penjualan. Profit tergantung banyak komponen biaya (bahan, tenaga kerja, gas, dll) yang bisa berubah-ubah dan rawan jadi bahan perdebatan soal 'biaya mana yang dihitung, mana yang tidak'. Basis Omzet menghindari potensi saling curiga soal laporan biaya ke depannya.
A39: 2. Kenapa basis Profit dianggap kurang adil di sini?
A40: Kalau basis Profit: pemilik tempat ikut menikmati hasil kerja keras & efisiensi usaha (semakin hemat biaya produksi, semakin besar juga bagian yang harus diserahkan), padahal dia tidak ikut menanggung modal maupun risiko rugi. Kalau basis Omzet: bagian pemilik tempat tetap proporsional terhadap besar kecilnya usaha, tapi risiko naik-turun biaya produksi sepenuhnya jadi tanggung jawab & hak pengusaha.
A41: 3. Kenapa 30% dianggap kegedean?
A42: Fasilitas yang benar-benar dipakai cuma lahan kosong (garasi/parkiran depan), tanpa akses dapur maupun listrik dari gedung. Ini setara dengan sewa lahan/space kosong kecil, BUKAN sewa unit usaha lengkap (dapur+listrik+ruang dalam). Sewa lahan kosong kecil di area serupa biasanya jauh di bawah nilai 30% dari keuntungan sebuah usaha F&B yang sedang berkembang.
A43: 4. Kalau tetap mau persentase, berapa yang wajar?
A44: Kalau tetap ingin pakai skema persentase (bukan flat), angka yang lazim dipakai untuk sewa lapak/space kecil pada usaha rumahan/UMKM F&B umumnya berkisar 3-7% dari OMZET (bukan profit) - contoh: 3% untuk space kecil tanpa fasilitas tambahan, naik ke 5-7% kalau ada fasilitas tambahan (listrik, akses dapur, dsb). Di luar rentang itu (misal 10%+ dari omzet, apalagi 30% dari profit) sudah tidak sebanding dengan skala kontribusi tempat yang diberikan.
A45: 5. Poin penutup
...
